<?xml version="1.0" encoding="UTF-8"?>
<robot xmlns:xacro="http://www.ros.org/wiki/xacro" name="poppy_ergo_jr">
  <xacro:arg name="lamp" default="false"/>
  <xacro:arg name="gripper" default="false"/>
  <link name="base_link">
    <visual>
      <origin xyz="0 0 0" rpy="0 0 0" />
      <geometry>
        <mesh filename="package://poppy_ergo_jr_description/meshes/base.dae" />
      </geometry>
      <material name="">
        <color rgba="0.752941176470588 0.752941176470588 0.752941176470588 1" />
      </material>
    </visual>
    <collision>
      <origin xyz="0 0.038 0.015" rpy="0 0 0" />
      <geometry>
        <cylinder length="0.03" radius="0.08" />
      </geometry>
    </collision>
  </link>
  <link name="long_U">
    <visual>
      <origin xyz="0 0 0" rpy="0 0 0" />
      <geometry>
        <mesh filename="package://poppy_ergo_jr_description/meshes/long_U.dae" />
      </geometry>
      <material name="">
        <color rgba="0.752941176470588 0.752941176470588 0.752941176470588 1" />
      </material>
    </visual>
    <collision>
      <origin xyz="0 0 0.01" rpy="0 0 0" />
      <geometry>
        <cylinder length="0.02" radius="0.02" />
      </geometry>
    </collision>
    <inertial>
      <mass value="0.1" />
      <inertia ixx="0.03" iyy="0.03" izz="0.03" ixy="0.0" ixz="0.0" iyz="0.0" />
    </inertial>
  </link>
  <joint name="m1" type="continuous">
    <origin xyz="0 0 0.0327993216120967" rpy="0 0 0" />
    <parent link="base_link" />
    <child link="long_U" />
    <axis xyz="0 0 1" />
  </joint>
  <link name="section_1">
    <visual>
      <origin xyz="0 0 0" rpy="0 1.5707963267949 0" />
      <geometry>
        <mesh filename="package://poppy_ergo_jr_description/meshes/section_1.dae" />
      </geometry>
      <material name="">
        <color rgba="0.752941176470588 0.752941176470588 0.752941176470588 1" />
      </material>
    </visual>
    <collision>
      <origin xyz="0.025 0 0" rpy="0 1.5707963267949 0" />
      <geometry>
        <cylinder length="0.05" radius="0.02" />
      </geometry>
    </collision>
    <inertial>
      <mass value="0.1" />
      <inertia ixx="0.03" iyy="0.03" izz="0.03" ixy="0.0" ixz="0.0" iyz="0.0" />
    </inertial>
  </link>
  <joint name="m2" type="continuous">
    <origin xyz="0 0 0.0240006783879033" rpy="0 -1.5707963267949 0" />
    <parent link="long_U" />
    <child link="section_1" />
    <axis xyz="0 0 -1" />
  </joint>
  <link name="section_2">
    <visual>
      <origin xyz="0 0 0" rpy="0 1.5707963267949 0" />
      <geometry>
        <mesh filename="package://poppy_ergo_jr_description/meshes/section_2.dae" />
      </geometry>
      <material name="">
        <color rgba="0.752941176470588 0.752941176470588 0.752941176470588 1" />
      </material>
    </visual>
    <collision>
      <origin xyz="0.025 0 0" rpy="0 1.5707963267949 0" />
      <geometry>
        <cylinder length="0.05" radius="0.02" />
      </geometry>
    </collision>
    <inertial>
      <mass value="0.1" />
      <inertia ixx="0.03" iyy="0.03" izz="0.03" ixy="0.0" ixz="0.0" iyz="0.0" />
    </inertial>
  </link>
  <joint name="m3" type="continuous">
    <origin xyz="0.054 0 0" rpy="0 0 0" />
    <parent link="section_1" />
    <child link="section_2" />
    <axis xyz="0 0 -1" />
  </joint>
  <link name="section_3">
    <visual>
      <origin xyz="0 0 0" rpy="0 3.14159268 0" />
      <geometry>
        <mesh filename="package://poppy_ergo_jr_description/meshes/section_3.dae" />
      </geometry>
      <material name="">
        <color rgba="0.752941176470588 0.752941176470588 0.752941176470588 1" />
      </material>
    </visual>
    <collision>
      <origin xyz="0 -0.025 0" rpy="1.5707963267949 0 0" />
      <geometry>
        <cylinder length="0.05" radius="0.02" />
      </geometry>
    </collision>
    <inertial>
      <mass value="0.1" />
      <inertia ixx="0.03" iyy="0.03" izz="0.03" ixy="0.0" ixz="0.0" iyz="0.0" />
    </inertial>
  </link>
  <joint name="m4" type="continuous">
    <origin xyz="0.045 0 0" rpy="0 -1.5707963267949 0" />
    <parent link="section_2" />
    <child link="section_3" />
    <axis xyz="0 0 -1" />
  </joint>
  <link name="section_4">
    <visual>
      <xacro:if value="$(arg lamp)">
        <origin xyz="0 0 0" rpy="0 -1.5707963267949 1.5707963267949" />
        <geometry>
          <mesh filename="package://poppy_ergo_jr_description/meshes/section_1.dae" />
        </geometry>
      </xacro:if>
      <xacro:if value="$(arg gripper)">
        <origin xyz="0 -0.058 0" rpy="0 -1.5707963267949 0" />
        <geometry>
          <mesh filename="package://poppy_ergo_jr_description/meshes/section_4.dae" />
        </geometry>
      </xacro:if>
      <material name="">
        <color rgba="0.752941176470588 0.752941176470588 0.752941176470588 1" />
      </material>
    </visual>
    <collision>
      <origin xyz="0 -0.035 0" rpy="1.5707963267949 0 0" />
      <geometry>
        <cylinder length="0.06" radius="0.02" />
        <box size="0.05 0.02 0.03" />
      </geometry>
    </collision>
    <inertial>
      <mass value="0.1" />
      <inertia ixx="0.03" iyy="0.03" izz="0.03" ixy="0.0" ixz="0.0" iyz="0.0" />
    </inertial>
  </link>
  <joint name="m5" type="continuous">
    <origin xyz="0 -0.048 0" rpy="0 -1.5707963267949 0" />
    <parent link="section_3" />
    <child link="section_4" />
    <axis xyz="0 0 1" />
  </joint>
  <link name="fixed_tip" />
  <joint name="t7f" type="fixed">
    <xacro:if value="$(arg lamp)">
      <origin xyz="0 -0.075 0" rpy="-1.5707963267949 0 0" />
      <parent link="section_5" />
    </xacro:if>
    <xacro:if value="$(arg gripper)">
      <origin xyz="0 -0.11 0" rpy="-1.5707963267949 0 0" />
      <parent link="section_4" />
    </xacro:if>
    <child link="fixed_tip" />
  </joint>
  <link name="section_5">
    <xacro:if value="$(arg lamp)">
      <visual>
        <origin xyz="0 0 0" rpy="0 0 1.5707963267949" />
        <geometry>
          <mesh filename="package://poppy_ergo_jr_description/meshes/lamp.dae" />
        </geometry>
        <material name="">
          <color rgba="0.752941176470588 0.752941176470588 0.752941176470588 1" />
        </material>
      </visual>
      <collision>
        <origin xyz="0 -0.045 0" rpy="1.5707963267949 0 0" />
        <geometry>
          <cylinder length="0.06" radius="0.03" />
          <box size="0.05 0.02 0.03" />
        </geometry>
      </collision>
    </xacro:if>
    <xacro:if value="$(arg gripper)">
      <visual>
        <origin xyz="0 0 0" rpy="0 0 0" />
        <geometry>
          <mesh filename="package://poppy_ergo_jr_description/meshes/gripper.dae" />
        </geometry>
        <material name="">
          <color rgba="0.752941176470588 0.752941176470588 0.752941176470588 1" />
        </material>
      </visual>
      <collision>
        <origin xyz="0 -0.04 0" rpy="-1.5707963267949 0 0" />
        <geometry>
          <cylinder length="0.06" radius="0.02" />
        </geometry>
      </collision>
    </xacro:if>
    <inertial>
      <mass value="0.1" />
      <inertia ixx="0.03" iyy="0.03" izz="0.03" ixy="0.0" ixz="0.0" iyz="0.0" />
    </inertial>
  </link>
  <joint name="m6" type="continuous">
    <xacro:if value="$(arg lamp)">
      <origin xyz="0 -0.054 0" rpy="0 0 0" />
      <axis xyz="0 0 1" />
    </xacro:if>
    <xacro:if value="$(arg gripper)">
      <origin xyz="0 -0.058 0" rpy="0 -1.5707963267949 0" />
      <axis xyz="0 0 -1" />
    </xacro:if>
    <parent link="section_4" />
    <child link="section_5" />
  </joint>
  <xacro:if value="$(arg gripper)">
    <link name="moving_tip" />
    <joint name="t7m" type="fixed">
      <origin xyz="0 -0.052 0" rpy="-1.5707963267949 0 0" />
      <parent link="section_5" />
      <child link="moving_tip" />
    </joint>
  </xacro:if>
  <transmission name="trans_m1">
    <type>transmission_interface/SimpleTransmission</type>
    <joint name="m1">
      <hardwareInterface>hardware_interface/EffortJointInterface</hardwareInterface>
    </joint>
    <actuator name="m1_motor">
      <hardwareInterface>hardware_interface/EffortJointInterface</hardwareInterface>
      <mechanicalReduction>1</mechanicalReduction>
    </actuator>
  </transmission>
  <transmission name="trans_m2">
    <type>transmission_interface/SimpleTransmission</type>
    <joint name="m2">
      <hardwareInterface>hardware_interface/EffortJointInterface</hardwareInterface>
    </joint>
    <actuator name="m2_motor">
      <hardwareInterface>hardware_interface/EffortJointInterface</hardwareInterface>
      <mechanicalReduction>1</mechanicalReduction>
    </actuator>
  </transmission>
  <transmission name="trans_m3">
    <type>transmission_interface/SimpleTransmission</type>
    <joint name="m3">
      <hardwareInterface>hardware_interface/EffortJointInterface</hardwareInterface>
    </joint>
    <actuator name="m3_motor">
      <hardwareInterface>hardware_interface/EffortJointInterface</hardwareInterface>
      <mechanicalReduction>1</mechanicalReduction>
    </actuator>
  </transmission>
  <transmission name="trans_m4">
    <type>transmission_interface/SimpleTransmission</type>
    <joint name="m4">
      <hardwareInterface>hardware_interface/EffortJointInterface</hardwareInterface>
    </joint>
    <actuator name="m4_motor">
      <hardwareInterface>hardware_interface/EffortJointInterface</hardwareInterface>
      <mechanicalReduction>1</mechanicalReduction>
    </actuator>
  </transmission>
  <transmission name="trans_m5">
    <type>transmission_interface/SimpleTransmission</type>
    <joint name="m5">
      <hardwareInterface>hardware_interface/EffortJointInterface</hardwareInterface>
    </joint>
    <actuator name="m5_motor">
      <hardwareInterface>hardware_interface/EffortJointInterface</hardwareInterface>
      <mechanicalReduction>1</mechanicalReduction>
    </actuator>
  </transmission>
  <transmission name="trans_m6">
    <type>transmission_interface/SimpleTransmission</type>
    <joint name="m6">
      <hardwareInterface>hardware_interface/EffortJointInterface</hardwareInterface>
    </joint>
    <actuator name="m6_motor">
      <hardwareInterface>hardware_interface/EffortJointInterface</hardwareInterface>
      <mechanicalReduction>1</mechanicalReduction>
    </actuator>
  </transmission>
  <gazebo>
    <plugin name="gazebo_ros_control" filename="libgazebo_ros_control.so">
      <robotNamespace>/</robotNamespace>
    </plugin>
  </gazebo>
</robot>